package util

import kotlin.coroutines.cancellation.CancellationException

inline fun <T, R> T.runCatchingCancellable(block: T.() -> R): Result<R> {
    return try {
        Result.success(block())
    } catch (e: Throwable) {
        if (e is CancellationException) {
            throw e
        }
        Result.failure(e)
    }
}
